Workbook

Sheet RESUMEN
A1: DISTRIBUIDORA CASTILLO YAÑEZ C.A | G1: F | H1: FACTURA | I1: =TODAY() -> 46057 | L1: 51364.043 | M1: 3860.551
A2: J-40214875-5 | G2: T | H2: TRANSFERENCIA | L2: 6090.28 | M2: =20*4.71 -> 94.2
A3: CEP 22405697 | G3: E | H3: EFECTIVO | I3: BCV | L3: =+L1-L2 -> 45273.763 | M3: =+M1-M2 -> 3766.351
A4: V72151 ZONA 1728 INICIO RUTA 4-6-2025 | G4: P | H4: PRESTADO | I4: 370.2544 | L4: 152.2 | M4: =2*4.71 -> 9.42
A5: =TODAY() -> 46057 | G5: O | H5: OBSEQUIO | L5: =+L3-L4 -> 45121.563 | M5: =+M3+M4 -> 3775.771
B6: TOTAL | D6: =SUM(D$10:D$1048576) -> 55145.994 | E6: =+E9*E7 -> 3961.3412 | F6: =+F7*F9 -> 31.842971 | G6: =+G7*G9 -> -217.41808 | H6: =(E6+F6+G6) -> 3775.7661 | L6: 412.68
B7: SUB TOTAL | E7: =SUM(E$10:E$1048576) -> 841 | F7: =SUM(F$10:F$1048576) -> 3 | G7: =SUM(G$10:G$1048576) -> -23 | H7: =SUM(H$10:H$1048576) -> 138.188 | L7: =+L5-L6 -> 44708.883
B8: DEUDOR | D8: MONTO | E8: VACIO 1/4 | F8: VACIO 355 | G8: VACIO 1.25 | H8: RETENCION | I8: VENDEDOR | J8: ULTIMO P O C | L8: 302.1
B9: RAZON SOCIAL | C9: NOMBRE CLIENTE | E9: =1744/I4 -> 4.7102749 | F9: =3930/I4 -> 10.614324 | G9: =3500/I4 -> 9.4529599 | H9: =+'MINI ABASTO EL SOL'!$G$5 -> 0 | L9: 5407.33
A10: 1 | B10: =+'ABASTO ANTONY'!$B$1 -> ABASTO ANTONY | C10: =+'ABASTO ANTONY'!$B$2 -> 0 | D10: =+'ABASTO ANTONY'!$C$3 -> 452.01 | E10: =+'ABASTO ANTONY'!$D$3 -> 1 | F10: =+'ABASTO ANTONY'!$E$3 -> 0 | G10: =+'ABASTO ANTONY'!$F$3 -> 0 | H10: =+'ABASTO ANTONY'!$G$3 -> 0 | I10: MENOR | J10: =MAX('ABASTO ANTONY'!A2:A1000) -> 46052 | L10: =+L7-L8+L9 -> 49814.113
A11: 2 | B11: =+'ABASTO DON MARCOS'!$B$1 -> ABASTO DON MARCOS | C11: =+'ABASTO DON MARCOS'!$B$2 -> ANA ZAMBRANO | D11: =+'ABASTO DON MARCOS'!$C$3 -> 98.01 | E11: =+'ABASTO DON MARCOS'!$D$3 -> 0 | F11: =+'ABASTO DON MARCOS'!$E$3 -> 0 | G11: =+'ABASTO DON MARCOS'!$F$3 -> 0 | H11: =+'ABASTO DON MARCOS'!$G$3 -> 0 | I11: WILLI | J11: =MAX('ABASTO DON MARCOS'!A2:A1000) -> 46055 | L11: 106.16
A12: 3 | B12: =+'ABASTO GLORIMAR'!$B$1 -> ABASTO GLORIMAR | C12: =+'ABASTO GLORIMAR'!$B$2 -> 0 | D12: =+'ABASTO GLORIMAR'!$C$3 -> 110.22 | E12: =+'ABASTO GLORIMAR'!$D$3 -> 2 | F12: =+'ABASTO GLORIMAR'!$E$3 -> 0 | G12: =+'ABASTO GLORIMAR'!$F$3 -> 0 | H12: =+'ABASTO GLORIMAR'!$G$3 -> 0 | I12: MENOR | J12: =MAX('ABASTO GLORIMAR'!A2:A1001) -> 46050 | L12: =+L10-L11 -> 49707.953
A13: 4 | B13: =+'ABASTO JAVER'!$B$1 -> ABASTO JAVER | C13: =+'ABASTO JAVER'!$B$2 -> JAVER OVALLES | D13: =+'ABASTO JAVER'!$C$3 -> 0 | E13: =+'ABASTO JAVER'!$D$3 -> 0 | F13: =+'ABASTO JAVER'!$E$3 -> 0 | G13: =+'ABASTO JAVER'!$F$3 -> 0 | H13: =+'ABASTO JAVER'!$G$3 -> 0 | I13: WILLI | J13: =MAX('ABASTO JAVER'!A2:A1002) -> 45979 | L13: 22.18
A14: 5 | B14: =+'ABASTO KLEIDI'!$B$1 -> ABASTO KLEIDI | C14: =+'ABASTO KLEIDI'!$B$2 -> KLEIDI | D14: =+'ABASTO KLEIDI'!$C$3 -> 1.35 | E14: =+'ABASTO KLEIDI'!$D$3 -> 0 | F14: =+'ABASTO KLEIDI'!$E$3 -> 0 | G14: =+'ABASTO KLEIDI'!$F$3 -> 0 | H14: =+'ABASTO KLEIDI'!$G$3 -> 0 | I14: MENOR | J14: =MAX('ABASTO KLEIDI'!A2:A1000) -> 46052 | L14: 46.28
A15: 6 | B15: =+'ABASTO LAUDA'!$B$1 -> ABASTO LAUDA | C15: =+'ABASTO LAUDA'!$B$2 -> ANDRES | D15: =+'ABASTO LAUDA'!$C$3 -> 816.14 | E15: =+'ABASTO LAUDA'!$D$3 -> 0 | F15: =+'ABASTO LAUDA'!$E$3 -> 0 | G15: =+'ABASTO LAUDA'!$F$3 -> 0 | H15: =+'ABASTO LAUDA'!$G$3 -> 0 | I15: MENOR | J15: =MAX('ABASTO LAUDA'!A2:A1000) -> 46050 | L15: 27.12
A16: 7 | B16: =+'ABASTO LAS CUADRAS'!$B$1 -> ABASTO LAS CUADRAS | C16: =+'ABASTO LAS CUADRAS'!$B$2 -> WILFREDO CHACON | D16: =+'ABASTO LAS CUADRAS'!$C$3 -> 128.3 | E16: =+'ABASTO LAS CUADRAS'!$D$3 -> 1 | F16: =+'ABASTO LAS CUADRAS'!$E$3 -> 0 | G16: =+'ABASTO LAS CUADRAS'!$F$3 -> 0 | H16: =+'ABASTO LAS CUADRAS'!$G$3 -> 0 | I16: WILLI | J16: =MAX('ABASTO LAS CUADRAS'!A2:A1000) -> 46051 | L16: 28.13
A17: 8 | B17: =+'ABASTO LAS MORENAS'!$B$1 -> ABASTO LAS MORENAS | C17: =+'ABASTO LAS MORENAS'!$B$2 -> CECILIO | D17: =+'ABASTO LAS MORENAS'!$C$3 -> 367.41 | E17: =+'ABASTO LAS MORENAS'!$D$3 -> 0 | F17: =+'ABASTO LAS MORENAS'!$E$3 -> 0 | G17: =+'ABASTO LAS MORENAS'!$F$3 -> 0 | H17: =+'ABASTO LAS MORENAS'!$G$3 -> 0 | I17: WILLI | J17: =MAX('ABASTO LAS MORENAS'!A2:A1000) -> 46052 | L17: 3093.39
A18: 9 | B18: =+'ABASTO LAS PILAS'!$B$1 -> ABASTO LAS PILAS | C18: =+'ABASTO LAS PILAS'!$B$2 -> 0 | D18: =+'ABASTO LAS PILAS'!$C$3 -> 46 | E18: =+'ABASTO LAS PILAS'!$D$3 -> 1 | F18: =+'ABASTO LAS PILAS'!$E$3 -> 0 | G18: =+'ABASTO LAS PILAS'!$F$3 -> 0 | H18: =+'ABASTO LAS PILAS'!$G$3 -> 0 | I18: MENOR | J18: =MAX('ABASTO LAS PILAS'!A2:A1000) -> 46051 | L18: =+L12-L13-L14-L15+L17-L16 -> 52677.633
A19: 10 | B19: =+'ABASTO LUZ VALERO'!$B$1 -> ABASTO LUZ VALERO | C19: =+'ABASTO LUZ VALERO'!$B$2 -> 0 | D19: =+'ABASTO LUZ VALERO'!$C$3 -> 187.67 | E19: =+'ABASTO LUZ VALERO'!$D$3 -> 0 | F19: =+'ABASTO LUZ VALERO'!$E$3 -> 0 | G19: =+'ABASTO LUZ VALERO'!$F$3 -> 0 | H19: =+'ABASTO LUZ VALERO'!$G$3 -> 0 | I19: MENOR | J19: =MAX('ABASTO LUZ VALERO'!A2:A1000) -> 46052 | L19: 260.75
A20: 11 | B20: =+'ABASTO LUZMAR'!$B$1 -> ABASTO LUZMAR | C20: =+'ABASTO LUZMAR'!$B$2 -> MARINA LUZ SANCHEZ | D20: =+'ABASTO LUZMAR'!$C$3 -> 0 | E20: =+'ABASTO LUZMAR'!$D$3 -> 0 | F20: =+'ABASTO LUZMAR'!$E$3 -> 0 | G20: =+'ABASTO LUZMAR'!$F$3 -> 0 | H20: =+'ABASTO LUZMAR'!$G$3 -> 0 | I20: WILLI | J20: =MAX('ABASTO LUZMAR'!A2:A1000) -> 45912 | L20: 844.35
A21: 12 | B21: =+'ABASTO MIS ANGELES'!$B$1 -> ABASTO MIS ANGELES | C21: =+'ABASTO MIS ANGELES'!$B$2 -> 0 | D21: =+'ABASTO MIS ANGELES'!$C$3 -> 50.18 | E21: =+'ABASTO MIS ANGELES'!$D$3 -> 0 | F21: =+'ABASTO MIS ANGELES'!$E$3 -> 0 | G21: =+'ABASTO MIS ANGELES'!$F$3 -> 0 | H21: =+'ABASTO MIS ANGELES'!$G$3 -> 0 | I21: MENOR | J21: =MAX('ABASTO MIS ANGELES'!A2:A1000) -> 46052 | L21: 4805.57
A22: 13 | B22: =+'ABASTO VANESA'!$B$1 -> ABASTO VANESA | C22: =+'ABASTO VANESA'!$B$2 -> 0 | D22: =+'ABASTO VANESA'!$C$3 -> 336.13 | E22: =+'ABASTO VANESA'!$D$3 -> 2 | F22: =+'ABASTO VANESA'!$E$3 -> 0 | G22: =+'ABASTO VANESA'!$F$3 -> 0 | H22: =+'ABASTO VANESA'!$G$3 -> 0 | I22: MENOR | J22: =MAX('ABASTO VANESA'!A2:A1000) -> 46052 | L22: =+L18-L19-L20+L21 -> 56378.103
A23: 14 | B23: =+'ABASTO Y CHARCUTERIA WILMARY'!$B$1 -> ABASTO Y CHARCUTERIA WILMARY | C23: =+'ABASTO Y CHARCUTERIA WILMARY'!$B$2 -> ANA CONTRERAS | D23: =+'ABASTO Y CHARCUTERIA WILMARY'!$C$3 -> 54.72 | E23: =+'ABASTO Y CHARCUTERIA WILMARY'!$D$3 -> 0 | F23: =+'ABASTO Y CHARCUTERIA WILMARY'!$E$3 -> 0 | G23: =+'ABASTO Y CHARCUTERIA WILMARY'!$F$3 -> 0 | H23: =+'ABASTO Y CHARCUTERIA WILMARY'!$G$3 -> 0 | I23: MENOR | J23: =MAX('ABASTO Y CHARCUTERIA WILMARY'!A2:A1000) -> 46051 | L23: 1232.14
A24: 15 | B24: =+'ABASTO YUDERLI'!$B$1 -> ABASTO YUDERLI | C24: =+'ABASTO YUDERLI'!$B$2 -> 0 | D24: =+'ABASTO YUDERLI'!$C$3 -> 0.02 | E24: =+'ABASTO YUDERLI'!$D$3 -> 1 | F24: =+'ABASTO YUDERLI'!$E$3 -> 0 | G24: =+'ABASTO YUDERLI'!$F$3 -> 0 | H24: =+'ABASTO YUDERLI'!$G$3 -> 0 | I24: MENOR | J24: =MAX('ABASTO YUDERLI'!A2:A1000) -> 45996 | L24: =+L22-L23 -> 55145.963
A25: 16 | B25: =+'ABASTO ZORANNY'!$B$1 -> ABASTO ZORANNY | C25: =+'ABASTO ZORANNY'!$B$2 -> ZORAIDA | D25: =+'ABASTO ZORANNY'!$C$3 -> 0 | E25: =+'ABASTO ZORANNY'!$D$3 -> 0 | F25: =+'ABASTO ZORANNY'!$E$3 -> 0 | G25: =+'ABASTO ZORANNY'!$F$3 -> 0 | H25: =+'ABASTO ZORANNY'!$G$3 -> 0 | I25: WILLI | J25: =MAX('ABASTO ZORANNY'!A2:A1000) -> 46050
A26: 17 | B26: =+'ALAS COMPAS'!$B$1 -> ALAS COMPRAS | C26: =+'ALAS COMPAS'!$B$2 -> ELICEO GARCIA | D26: =+'ALAS COMPAS'!$C$3 -> 541.04 | E26: =+'ALAS COMPAS'!$D$3 -> 0 | F26: =+'ALAS COMPAS'!$E$3 -> 0 | G26: =+'ALAS COMPAS'!$F$3 -> 0 | H26: =+'ALAS COMPAS'!$G$3 -> 0 | I26: WILLI | J26: =MAX('ALAS COMPAS'!A2:A1000) -> 46052
A27: 18 | B27: =+'ALVARO RINCON'!$B$1 -> ALVARO RINCON | C27: =+'ALVARO RINCON'!$B$2 -> 0 | D27: =+'ALVARO RINCON'!$C$3 -> 0 | E27: =+'ALVARO RINCON'!$D$3 -> 0 | F27: =+'ALVARO RINCON'!$E$3 -> 0 | G27: =+'ALVARO RINCON'!$F$3 -> 0 | H27: =+'ALVARO RINCON'!$G$3 -> 0 | I27: MENOR | J27: =MAX('ALVARO RINCON'!A2:A1000) -> 0
A28: 19 | B28: =+'ALEJANDRA NIETO'!$B$1 -> ALEJANDRA NIETO | C28: =+'ALEJANDRA NIETO'!$B$2 -> 0 | D28: =+'ALEJANDRA NIETO'!$C$3 -> -2.21 | E28: =+'ALEJANDRA NIETO'!$D$3 -> 0 | F28: =+'ALEJANDRA NIETO'!$E$3 -> 0 | G28: =+'ALEJANDRA NIETO'!$F$3 -> 0 | H28: =+'ALEJANDRA NIETO'!$G$3 -> 0 | I28: MENOR | J28: =MAX('ALEJANDRA NIETO'!A2:A1000) -> 46055
A29: 20 | B29: =+AMALUBE!$B$1 -> AMALUBE | C29: =+AMALUBE!$B$2 -> 0 | D29: =+AMALUBE!$C$3 -> 33.85 | E29: =+AMALUBE!$D$3 -> 0 | F29: =+AMALUBE!$E$3 -> 0 | G29: =+AMALUBE!$F$3 -> 0 | H29: =+AMALUBE!$G$3 -> 0 | I29: MENOR | J29: =MAX(AMALUBE!A2:A1000) -> 46050
A30: 21 | B30: =+'AMEZQUITA BODEGON'!$B$1 -> AMEZQUITA BODEGON | C30: =+'AMEZQUITA BODEGON'!$B$2 -> 0 | D30: =+'AMEZQUITA BODEGON'!$C$3 -> 335.58 | E30: =+'AMEZQUITA BODEGON'!$D$3 -> 1 | F30: =+'AMEZQUITA BODEGON'!$E$3 -> 0 | G30: =+'AMEZQUITA BODEGON'!$F$3 -> 0 | H30: =+'AMEZQUITA BODEGON'!$G$3 -> 0 | I30: WILLI
A31: 22 | B31: =+'ANDERZON POLAR'!$B$1 -> ANDERZON POLAR | C31: =+'ANDERZON POLAR'!$B$2 -> 0 | D31: =+'ANDERZON POLAR'!$C$3 -> 0.25 | E31: =+'ANDERZON POLAR'!$D$3 -> 0 | F31: =+'ANDERZON POLAR'!$E$3 -> 0 | G31: =+'ANDERZON POLAR'!$F$3 -> 0 | H31: =+'ANDERZON POLAR'!$G$3 -> 0 | I31: WILLI | J31: =MAX('ANDERZON POLAR'!A2:A1000) -> 46036
A32: 23 | B32: =+'ANDERZON RODRIGUEZ'!$B$1 -> ANDERZON RODRIGUEZ | C32: =+'ANDERZON RODRIGUEZ'!$B$2 -> 0 | D32: =+'ANDERZON RODRIGUEZ'!$C$3 -> 127.18 | E32: =+'ANDERZON RODRIGUEZ'!$D$3 -> 0 | F32: =+'ANDERZON RODRIGUEZ'!$E$3 -> -1 | G32: =+'ANDERZON RODRIGUEZ'!$F$3 -> -2 | H32: =+'ANDERZON RODRIGUEZ'!$G$3 -> 0 | I32: MENOR | J32: =MAX('ANDERZON RODRIGUEZ'!A2:A1000) -> 46056
A33: 24 | B33: =+'ANDREA URDANETA'!$B$1 -> ANDREA URDANETA | C33: =+'ANDREA URDANETA'!$B$2 -> 0 | D33: =+'ANDREA URDANETA'!$C$3 -> 368.59 | E33: =+'ANDREA URDANETA'!$D$3 -> 0 | F33: =+'ANDREA URDANETA'!$E$3 -> 0 | G33: =+'ANDREA URDANETA'!$F$3 -> 0 | H33: =+'ANDREA URDANETA'!$G$3 -> 0 | I33: MENOR | J33: =MAX('ANDREA URDANETA'!A2:A1000) -> 46052
A34: 25 | B34: =+APRICOT!$B$1 -> APRICOT | C34: =+APRICOT!$B$2 -> 0 | D34: =+APRICOT!$C$3 -> 440.72 | E34: =+APRICOT!$D$3 -> 12 | F34: =+APRICOT!$E$3 -> 0 | G34: =+APRICOT!$F$3 -> 0 | H34: =+APRICOT!$G$3 -> 0 | I34: ROBERTO | J34: =MAX(APRICOT!A2:A1000) -> 46045
A35: 26 | B35: =+'AURA VIVAS'!$B$1 -> AURA VIVAS | C35: =+'AURA VIVAS'!$B$2 -> 0 | D35: =+'AURA VIVAS'!$C$3 -> -0.002 | E35: =+'AURA VIVAS'!$D$3 -> 0 | F35: =+'AURA VIVAS'!$E$3 -> 0 | G35: =+'AURA VIVAS'!$F$3 -> 0 | H35: =+'AURA VIVAS'!$G$3 -> 0 | I35: WILLI | J35: =MAX('AURA VIVAS'!A2:A1000) -> 45950
B36: =+'AVENTURA INFLABLE'!$B$1 -> AVENTURA INFLABLE | C36: =+'AVENTURA INFLABLE'!$B$2 -> 0 | D36: =+'AVENTURA INFLABLE'!$C$3 -> 1.9539925e-13 | E36: =+'AVENTURA INFLABLE'!$D$3 -> 2 | F36: =+'AVENTURA INFLABLE'!$E$3 -> 0 | G36: =+'AVENTURA INFLABLE'!$F$3 -> 0 | H36: =+'AVENTURA INFLABLE'!$G$3 -> 0 | I36: MENOR
B37: =+'BARBERIA SPARTA'!$B$1 -> BARBERIA SPARTA | C37: =+'BARBERIA SPARTA'!$B$2 -> 0 | D37: =+'BARBERIA SPARTA'!$C$3 -> 0 | E37: =+'BARBERIA SPARTA'!$D$3 -> 0 | F37: =+'BARBERIA SPARTA'!$E$3 -> 0 | G37: =+'BARBERIA SPARTA'!$F$3 -> 0 | H37: =+'BARBERIA SPARTA'!$G$3 -> 0 | I37: MENOR
A38: 27 | B38: =+'BAKAI MACHIRI'!$B$1 -> BAKAI MACHIRI | C38: =+'BAKAI MACHIRI'!$B$2 -> 0 | D38: =+'BAKAI MACHIRI'!$C$3 -> 71.28 | E38: =+'BAKAI MACHIRI'!$D$3 -> 0 | F38: =+'BAKAI MACHIRI'!$E$3 -> 0 | G38: =+'BAKAI MACHIRI'!$F$3 -> 0 | H38: =+'BAKAI MACHIRI'!$G$3 -> 44.73 | I38: MENOR | J38: =MAX('BAKAI MACHIRI'!A2:A1000) -> 46056
A39: 28 | B39: =+'BELKIS MONSALVE'!$B$1 -> BELKIS MONSALVE | C39: =+'BELKIS MONSALVE'!$B$2 -> 0 | D39: =+'BELKIS MONSALVE'!$C$3 -> 0 | E39: =+'BELKIS MONSALVE'!$D$3 -> 0 | F39: =+'BELKIS MONSALVE'!$E$3 -> 0 | G39: =+'BELKIS MONSALVE'!$F$3 -> 0 | H39: =+'BELKIS MONSALVE'!$G$3 -> 0 | I39: WILLI | J39: =MAX('BELKIS MONSALVE'!A2:A1000) -> 0
A40: 29 | B40: =+'BOD ALTOS PARAMILLO'!$B$1 -> BOD ALTOS PARAMILLO | C40: =+'BOD ALTOS PARAMILLO'!$B$2 -> CIRA PERDOMO | D40: =+'BOD ALTOS PARAMILLO'!$C$3 -> -0.02 | E40: =+'BOD ALTOS PARAMILLO'!$D$3 -> 0 | F40: =+'BOD ALTOS PARAMILLO'!$E$3 -> 0 | G40: =+'BOD ALTOS PARAMILLO'!$F$3 -> 0 | H40: =+'BOD ALTOS PARAMILLO'!$G$3 -> 0 | I40: WILLI | J40: =MAX('BOD ALTOS PARAMILLO'!A2:A1000) -> 45958
...

Sheet ABASTO ANTONY
A1: CLIENTE | B1: ABASTO ANTONY
A2: NOMBRE
A3: TOTALES | C3: =SUM(C$4:C$1048576) -> 452.01 | D3: =SUM(D$4:D$1048576) -> 1 | E3: =SUM(E$5:E$1048576) -> 0 | F3: =SUM(F$5:F$1048576) -> 0 | G3: =SUM(G$5:G$1048576) -> 0
A4: FECHA | B4: F- E- T- | C4: DEUDA Y ABONOS | D4: VACIO 1/4 | E4: VACIO 350 | F4: VACIO 1.25 | G4: RETECION
A5: 45815 | B5: F | C5: 53.29 | D5: 1
A6: 45815 | B6: F | C6: 70.6
A7: 45815 | B7: F | C7: 47.6
A8: 45821 | B8: T | C8: -171.49
A9: 45821 | B9: F | C9: 48.5
A10: 45821 | B10: F | C10: 18.5
A11: 45821 | B11: F | C11: 245.76
A12: 45828 | B12: F | C12: 30.8 | D12: -1
A13: 45828 | B13: F | C13: 52.06
A14: 45828 | B14: F | C14: 60.4
A15: 45831 | B15: T | C15: -312.75
A16: 45838 | B16: T | C16: -143.26
A17: 45842 | B17: F | C17: 82.23
A18: 45842 | B18: F | C18: 93.28
A19: 45842 | B19: F | C19: 16.62
A20: 45849 | B20: T | C20: -192.13
A21: 45849 | B21: F | C21: 96.57
A22: 45849 | B22: F | C22: 18.29
A23: 45849 | B23: F | C23: 39.32
A24: 45849 | B24: F | C24: 62.4 | D24: 3
A25: 45859 | B25: T | C25: -216.59
A26: 45859 | B26: T | C26: -181.58
A27: 45856 | B27: F | C27: 105.03 | D27: -2
A28: 45856 | B28: F | C28: =72.61+3.91 -> 76.52
A29: 45863 | B29: F | C29: 58.9
A30: 45863 | B30: F | C30: 92.16
A31: 45867 | B31: T | C31: -1029.72
A32: 45867 | B32: T | C32: -151.06
A33: 45867 | B33: F | C33: 39
A34: 45867 | B34: F | C34: 863.4
A35: 45867 | B35: F | C35: 117.32
A36: 45870 | B36: F | C36: 137.01
A37: 45870 | B37: F | C37: 148.71
A38: 45870 | B38: F | C38: 9.86
A39: 45877 | B39: T | C39: -295.58
A40: 45877 | B40: T | C40: -384.42
...

Sheet ABASTO DON MARCOS
A1: CLIENTE | B1: ABASTO DON MARCOS
A2: NOMBRE | B2: ANA ZAMBRANO
A3: TOTALES | C3: =SUM(C$4:C$1048576) -> 98.01 | D3: =SUM(D$4:D$1048576) -> 0 | E3: =SUM(E$5:E$1048576) -> 0 | F3: =SUM(F$5:F$1048576) -> 0 | G3: =SUM(G$5:G$1048576) -> 0
A4: FECHA | B4: F- E- T- | C4: DEUDA Y ABONOS | D4: VACIO 1/4 | E4: VACIO 350 | F4: VACIO 1.25 | G4: RETECION
A5: 45848 | B5: F | C5: 15.85
A6: 45863 | B6: T | C6: -15.86
A7: 45869 | B7: F | C7: 41
A8: 45880 | B8: T | C8: -40.42
A9: 45877 | B9: F | C9: 34.98
A10: 45889 | B10: T | C10: -29.62
A11: 45893 | B11: T | C11: -62.47
A12: 45891 | B12: F | C12: 113.83
A13: 45899 | B13: F | C13: 46.83
A14: 45901 | B14: T | C14: -46.83
A15: 45901 | B15: T | C15: -25.73
A16: 45901 | B16: T | C16: -31.27
... A53: 46055 | B53: T | C53: -130

Sheet ABASTO GLORIMAR
A1: CLIENTE | B1: ABASTO GLORIMAR
A2: NOMBRE
A3: TOTALES | C3: =SUM(C$4:C$1048576) -> 110.22 | D3: =SUM(D$4:D$1048576) -> 2 | E3: =SUM(E$5:E$1048576) -> 0 | F3: =SUM(F$5:F$1048576) -> 0 | G3: =SUM(G$5:G$1048576) -> 0
A4: FECHA | B4: F- E- T- | C4: DEUDA Y ABONOS | D4: VACIO 1/4 | E4: VACIO 350 | F4: VACIO 1.25 | G4: RETECION
A5: 45815 | B5: F | C5: 44.6
A6: 45815 | B6: F | C6: 61.9
A7: 45817 | B7: T | C7: -106.54
A8: 45820 | B8: F | C8: 48.2
A9: 45820 | B9: F | C9: 35.6
A10: 45827 | B10: T | C10: -83.28
A11: 45827 | B11: F | C11: 1514 | D11: 11
A12: 45827 | B12: F | C12: 15.85
A13: 45834 | B13: T | C13: -1529.85
A14: 45834 | B14: F | C14: 579.8 | D14: -7
A15: 45834 | B15: F | C15: 29.34
A16: 45835 | B16: T | C16: -459.14
A17: 45841 | B17: T | C17: -150
A18: 45841 | B18: V | D18: -4
A19: 45841 | B19: F | C19: 31.7
A20: 45845 | B20: T | C20: -31.78
A21: 45848 | B21: F | C21: 1472.6 | D21: 24
A22: 45848 | B22: F | C22: 25.69
A23: 45848 | B23: F | C23: 15.1
A24: 45848 | B24: F | C24: 145.28
A25: 45848 | B25: F | C25: 21.56
A26: 45852 | B26: E | C26: -1497.29
A27: 45860 | B27: F | C27: 385.5 | D27: -24
A28: 45860 | B28: F | C28: 62.7
A29: 45866 | B29: T | C29: -182.4
A30: 45866 | B30: T | C30: -449.14
A31: 45868 | B31: F | C31: 363.6
A32: 45873 | B32: T | C32: -363.6
A33: 45875 | B33: F | C33: 1129.2
A34: 45875 | B34: F | C34: 96.44
A35: 45876 | B35: T | C35: -612.82
A36: 45876 | B36: T | C36: -612.82
A37: 45876 | B37: T | C37: -542.41
A38: 45877 | B38: T | C38: -390.39
A39: 45877 | B39: F | C39: 932.8 | D39: 46
A40: 45882 | B40: F | C40: 35.4 | D40: -33
...

Sheet ABASTO JAVER
A1: CLIENTE | B1: ABASTO JAVER
A2: NOMBRE | B2: JAVER OVALLES
A3: TOTALES | C3: =SUM(C$4:C$1048576) -> 0 | D3: =SUM(D$4:D$1048576) -> 0 | E3: =SUM(E$5:E$1048576) -> 0 | F3: =SUM(F$5:F$1048576) -> 0 | G3: =SUM(G$5:G$1048576) -> 0
A4: FECHA | B4: F- E- T- | C4: DEUDA Y ABONOS | D4: VACIO 1/4 | E4: VACIO 350 | F4: VACIO 1.25 | G4: RETECION
A5: 45831 | B5: F | C5: 59.18
A6: 45835 | B6: F | C6: 12.1
A7: 45839 | B7: T | C7: -79.41
A8: 45839 | B8: T | C8: -87.1
A9: 45839 | B9: F | C9: 87.1
A10: 45846 | B10: F | C10: 54.18
A11: 45847 | B11: F | C11: 90
A12: 45848 | B12: T | C12: -90
A13: 45853 | B13: E | C13: -46.06
A14: 45853 | B14: F | C14: 26.15
A15: 45860 | B15: T | C15: -167.13
A16: 45860 | B16: F | C16: 389.72
... A40: 45979 | B40: T | C40: -16.31

Sheet ABASTO KLEIDI
A1: CLIENTE | B1: ABASTO KLEIDI
A2: NOMBRE | B2: KLEIDI
A3: TOTALES | C3: =SUM(C$4:C$1048576) -> 1.35 | D3: =SUM(D$4:D$1048576) -> 0 | E3: =SUM(E$5:E$1048576) -> 0 | F3: =SUM(F$5:F$1048576) -> 0 | G3: =SUM(G$5:G$1048576) -> 0
A4: FECHA | B4: F- E- T- | C4: DEUDA Y ABONOS | D4: VACIO 1/4 | E4: VACIO 350 | F4: VACIO 1.25 | G4: RETECION
A5: 45815 | B5: T | C5: -15.85
A6: 45815 | B6: F | C6: 15.85
A7: 45870 | B7: F | C7: 15.85
A8: 45870 | B8: F | C8: 47.76
A9: 45884 | B9: E | C9: -63.61
A10: 45884 | B10: F | C10: 33.6
A11: 45898 | B11: F | C11: 20.93
A12: 45903 | B12: T | C12: -33.81
A13: 45912 | B13: E | C13: -20.93
A14: 45912 | B14: F | C14: 24.93
A15: 45933 | B15: E | C15: -24.73
A16: 45933 | B16: F | C16: 31.16
... A27: 46052 | B27: E | C27: -17.24

Sheet ABASTO LAUDA
A1: don | B1: ABASTO LAUDA
A2: NOMBRE | B2: ANDRES
A3: TOTALES | C3: =SUM(C$4:C$1048576) -> 816.14 | D3: =SUM(D$4:D$1048576) -> 0 | E3: =SUM(E$5:E$1048576) -> 0 | F3: =SUM(F$5:F$1048576) -> 0 | G3: =SUM(G$5:G$1048576) -> 0
A4: FECHA | B4: F- E- T- | C4: DEUDA Y ABONOS | D4: VACIO 1/4 | E4: VACIO 350 | F4: VACIO 1.25 | G4: RETECION
A5: 45820 | B5: F | C5: 27.48
A6: 45820 | B6: F | C6: 360.98
A7: 45824 | B7: T | C7: -384.37
A8: 45833 | B8: F | C8: 19.68
A9: 45833 | B9: F | C9: 185.25
A10: 45834 | B10: T | C10: -209.05
A11: 45840 | B11: F | C11: 31.7
A12: 45840 | B12: F | C12: 160.46
A13: 45841 | B13: T | C13: -192.16
A14: 45854 | B14: T | C14: -170.73
A15: 45854 | B15: F | C15: 61.22
A16: 45854 | B16: F | C16: 109.48
... A36: 45931 | B36: T | C36: -335.87
A37: 45931 | B37: F | C37: 92.92 | D37: 4
A38: 45931 | B38: F | C38: 194.96
A39: 45932 | B39: V | D39: -3
A40: 45938 | B40: T | C40: -179.15
A41: 45938 | B41: F | C41: 13.5
A42: 45938 | B42: F | C42: 119.65
A43: 45938 | B43: F | C43: 46
A44: 45945 | B44: T | C44: -20.59
A45: 45945 | B45: T | C45: -100.45
A46: 45945 | B46: F | C46: 19.68
A47: 45945 | B47: F | C47: 78.36
A48: 45945 | B48: F | C48: 23
A49: 45947 | B49: T | C49: -117
A50: 45947 | B50: V | D50: -1
A51: 45947 | B51: F | C51: 117
A52: 45952 | B52: T | C52: -597.46
A53: 45952 | B53: F | C53: 360.06
A54: 45952 | B54: F | C54: 191.4
A55: 45952 | B55: F | C55: 46
A56: 45959 | B56: T | C56: -152.9
A57: 45959 | B57: F | C57: 35.28
A58: 45959 | B58: F | C58: 94.62
A59: 45959 | B59: F | C59: 23
...

Sheet ABASTO LAS CUADRAS
A1: CLIENTE | B1: ABASTO LAS CUADRAS
A2: NOMBRE | B2: WILFREDO CHACON
A3: TOTALES | C3: =SUM(C$4:C$1048576) -> 128.3 | D3: =SUM(D$4:D$1048576) -> 1 | E3: =SUM(E$5:E$1048576) -> 0 | F3: =SUM(F$5:F$1048576) -> 0 | G3: =SUM(G$5:G$1048576) -> 0
A4: FECHA | B4: F- E- T- | C4: DEUDA Y ABONOS | D4: VACIO 1/4 | E4: VACIO 350 | F4: VACIO 1.25 | G4: RETECION
A5: 45820 | B5: F | C5: 15.85
A6: 45820 | B6: F | C6: 109.42
A7: 45825 | B7: T | C7: -125.26
A8: 45828 | B8: F | C8: 9.84
A9: 45828 | B9: F | C9: 173.62
A10: 45831 | B10: T | C10: -183.46
A11: 45841 | B11: F | C11: 125.58
A12: 45848 | B12: T | C12: -125.58
A13: 45860 | B13: F | C13: 15.85 | D13: 1
A14: 45860 | B14: F | C14: 236.24
A15: 45862 | B15: T | C15: -252.07
A16: 45866 | B16: T | C16: -140.64
A17: 45867 | B17: F | C17: 140.64
A18: 45869 | B18: F | C18: 17.46
A19: 45869 | B19: F | C19: 189.85
A20: 45874 | B20: T | C20: -236.02
A21: 45876 | B21: F | C21: 25.34
A22: 45876 | B22: F | C22: 3.21
A23: 45883 | B23: F | C23: 15
A24: 45883 | B24: F | C24: 82.26
A25: 45883 | B25: F | C25: 30.04
A26: 45887 | B26: T | C26: -127.3
A27: 45889 | B27: F | C27: 43.27 | D27: 1
A28: 45889 | B28: F | C28: 445.32
A29: 45889 | B29: F | C29: 77.2
A30: 45890 | B30: T | C30: -110.14
A31: 45894 | B31: T | C31: -457.64
A32: 45897 | B32: F | C32: 15
A33: 45897 | B33: F | C33: 118.44
A34: 45897 | B34: F | C34: 17.7
A35: 45898 | B35: F | C35: 21.9
A36: 45898 | B36: D | C36: -17.7
A37: 45898 | B37: T | C37: -21.9
A38: 45901 | B38: T | C38: -133.7
A39: 45912 | B39: F | C39: 30.85
... A50: 45946 | B50: T | C50: -47.49
...

Sheet ABASTO LAS MORENAS
A1: CLIENTE | B1: ABASTO LAS MORENAS
A2: NOMBRE | B2: CECILIO
A3: TOTALES | C3: =SUM(C$4:C$1048576) -> 367.41 | D3: =SUM(D$4:D$1048576) -> 0 | E3: =SUM(E$5:E$1048576) -> 0 | F3: =SUM(F$5:F$1048576) -> 0 | G3: =SUM(G$5:G$1048576) -> 0
A4: FECHA | B4: F- E- T- | C4: DEUDA Y ABONOS | D4: VACIO 1/4 | E4: VACIO 350 | F4: VACIO 1.25 | G4: RETECION
A5: 45815 | B5: F | C5: 33.39
A6: 45815 | B6: F | C6: 82.1
A7: 45824 | B7: T | C7: -115.49
A8: 45828 | B8: F | C8: 28.55
A9: 45828 | B9: F | C9: 156.82
A10: 45835 | B10: T | C10: -185
A11: 45835 | B11: F | C11: 19.68
A12: 45835 | B12: F | C12: 98.86
A13: 45842 | B13: T | C13: -67.84
A14: 45842 | B14: F | C14: 15.85
A15: 45842 | B15: F | C15: 95.88
A16: 45848 | B16: T | C16: -51.08
... A109: 46052 | B109: F | C109: 294.15

Sheet ABASTO LAS PILAS
A1: CLIENTE | B1: ABASTO LAS PILAS
A2: NOMBRE
A3: TOTALES | C3: =SUM(C$4:C$1048576) -> 46 | D3: =SUM(D$4:D$1048576) -> 1 | E3: =SUM(E$5:E$1048576) -> 0 | F3: =SUM(F$5:F$1048576) -> 0 | G3: =SUM(G$5:G$1048576) -> 0
A4: FECHA | B4: F- E- T- | C4: DEUDA Y ABONOS | D4: VACIO 1/4 | E4: VACIO 350 | F4: VACIO 1.25 | G4: RETECION
A5: 45820 | B5: F | C5: 33.49
A6: 45820 | B6: F | C6: 12.8
A7: 45826 | B7: E | C7: -46.29
A8: 45826 | B8: F | C8: 19.5
A9: 45826 | B9: F | C9: 20.8
A10: 45831 | B10: T | C10: -40.3
A11: 45833 | B11: F | C11: 31.7
A12: 45834 | B12: T | C12: -31.7
A13: 45840 | B13: F | C13: 41.6
A14: 45847 | B14: T | C14: -41.6
A15: 45848 | B15: F | C15: 33.49
A16: 45848 | B16: F | C16: 20.8
A17: 45854 | B17: E | C17: -54.31
A18: 45862 | B18: F | C18: 35.53 | D18: 1
A19: 45862 | B19: F | C19: 41.6
A20: 45869 | B20: E | C20: -77.13
A21: 45869 | B21: F | C21: 20.8 | D21: -1
A22: 45876 | B22: E | C22: -20.8
A23: 45883 | B23: F | C23: 41.54
A24: 45883 | B24: F | C24: 20.8
A25: 45890 | B25: T | C25: -62.35
A26: 45890 | B26: F | C26: 20.8
A27: 45895 | B27: T | C27: -20.8
A28: 45909 | B28: F | C28: 62.83 | D28: 1
A29: 45909 | B29: F | C29: 62.4
A30: 45912 | B30: T | C30: -125.23
A31: 45918 | B31: F | C31: 20.8 | D31: -1
A32: 45924 | B32: T | C32: -20.8
A33: 45925 | B33: F | C33: 15.85
A34: 45925 | B34: F | C34: 20.8
A35: 45932 | B35: T | C35: -36.65
A36: 45932 | B36: F | C36: 25.69
A37: 45940 | B37: T | C37: -25.69
A38: 45940 | B38: F | C38: 23
A39: 45942 | B39: T | C39: -23
A40: 45947 | B40: F | C40: 26.25
...

Sheet ABASTO LUZ VALERO
A1: CLIENTE | B1: ABASTO LUZ VALERO
A2: NOMBRE
A3: TOTALES | C3: =SUM(C$4:C$1048576) -> 187.67 | D3: =SUM(D$4:D$1048576) -> 0 | E3: =SUM(E$5:E$1048576) -> 0 | F3: =SUM(F$5:F$1048576) -> 0 | G3: =SUM(G$5:G$1048576) -> 0
A4: FECHA | B4: F- E- T- | C4: DEUDA Y ABONOS | D4: VACIO 1/4 | E4: VACIO 350 | F4: VACIO 1.25 | G4: RETECION
A5: 45929 | B5: F | C5: 25.69
A6: 45929 | B6: F | C6: 21.4
A7: 45933 | B7: T | C7: -47.09
A8: 45933 | B8: F | C8: 22.5
A9: 45933 | B9: F | C9: 67.28
A10: 45939 | B10: T | C10: -45.46
A11: 45940 | B11: F | C11: 103.33
A12: 45942 | B12: T | C12: -44.32
A13: 45945 | B13: T | C13: -66.97
A14: 45947 | B14: F | C14: 116.86
A15: 45950 | B15: T | C15: -128.86
A16: 45961 | B16: T | C16: -36.36
... A39: 46052 | B39: F | C39: 187.7

Sheet ABASTO LUZMAR
A1: CLIENTE | B1: ABASTO LUZMAR
A2: NOMBRE | B2: MARINA LUZ SANCHEZ
A3: TOTALES | C3: =SUM(C$4:C$1048576) -> 0 | D3: =SUM(D$4:D$1048576) -> 0 | E3: =SUM(E$5:E$1048576) -> 0 | F3: =SUM(F$5:F$1048576) -> 0 | G3: =SUM(G$5:G$1048576) -> 0
A4: FECHA | B4: F- E- T- | C4: DEUDA Y ABONOS | D4: VACIO 1/4 | E4: VACIO 350 | F4: VACIO 1.25 | G4: RETECION
A5: 45821 | B5: F | C5: 15.4
A6: 45828 | B6: T | C6: -15.4
A7: 45912 | B7: T | C7: -38.14
A8: 45912 | B8: F | C8: 20.8
A9: 45912 | B9: F | C9: 17.34

Sheet ABASTO MIS ANGELES
A1: CLIENTE | B1: ABASTO MIS ANGELES
A2: NOMBRE
A3: TOTALES | C3: =SUM(C$4:C$1048576) -> 50.18 | D3: =SUM(D$4:D$1048576) -> 0 | E3: =SUM(E$5:E$1048576) -> 0 | F3: =SUM(F$5:F$1048576) -> 0 | G3: =SUM(G$5:G$1048576) -> 0
A4: FECHA | B4: F- E- T- | C4: DEUDA Y ABONOS | D4: VACIO 1/4 | E4: VACIO 350 | F4: VACIO 1.25 | G4: RETECION
A5: 45870 | B5: F | C5: 48.78
A6: 45877 | B6: E | C6: -8
A7: 45891 | B7: E | C7: -40.8
A8: 45891 | B8: F | C8: 29.92
A9: 45898 | B9: E | C9: -29.93
A10: 45898 | B10: F | C10: 15.12
A11: 45912 | B11: E | C11: -15.12
A12: 45912 | B12: F | C12: 15.85
A13: 45912 | B13: F | C13: 22.8
A14: 45926 | B14: E | C14: -38.67
A15: 45926 | B15: F | C15: 23.42
A16: 45940 | B16: E | C16: -23.42
... A30: 46052 | B30: E | C30: -13.1

Sheet ABASTO VANESA
A1: CLIENTE | B1: ABASTO VANESA
A2: NOMBRE
A3: TOTALES | C3: =SUM(C$4:C$1048576) -> 336.13 | D3: =SUM(D$4:D$1048576) -> 2 | E3: =SUM(E$5:E$1048576) -> 0 | F3: =SUM(F$5:F$1048576) -> 0 | G3: =SUM(G$5:G$1048576) -> 0
A4: FECHA | B4: F- E- T- | C4: DEUDA Y ABONOS | D4: VACIO 1/4 | E4: VACIO 350 | F4: VACIO 1.25 | G4: RETECION
A5: 45815 | B5: F | C5: 12.7
A6: 45815 | B6: F | C6: 144
A7: 45821 | B7: T | C7: -156.7
A8: 45828 | B8: F | C8: 28.55
A9: 45828 | B9: F | C9: 24.84
A10: 45828 | B10: F | C10: 20.8
A11: 45835 | B11: T | C11: -74.19
A12: 45835 | B12: F | C12: 145.6
A13: 45835 | B13: F | C13: 51.38
A14: 45835 | B14: F | C14: 9.45
A15: 45842 | B15: T | C15: -206.43
A16: 45842 | B16: F | C16: 34.04
... A58: 45933 | B58: T | C58: -221.2
A59: 45933 | B59: F | C59: 27.85 | D59: 1
A60: 45933 | B60: F | C60: 94.12
A61: 45933 | B61: F | C61: 184.8
A62: 45940 | B62: T | C62: -306.77
A63: 45940 | B63: F | C63: 230
A64: 45947 | B64: T | C64: -489.02
A65: 45947 | B65: F | C65: 32.76
A66: 45947 | B66: F | C66: 70.2
A67: 45947 | B67: F | C67: 386.06
A68: 45954 | B68: T | C68: -230
A69: 45954 | B69: F | C69: 37.98
A70: 45954 | B70: F | C70: 47.2
A71: 45954 | B71: F | C71: 69
... A79: 45975 | B79: T | C79: -182.41
A80: 45975 | B80: F | C80: 231.71 | D80: 1
A81: 45982 | B81: F | C81: 361.52
A82: 45985 | B82: T | C82: -230.25
A83: 45989 | B83: T | C83: -361.52
A84: 45989 | B84: F | C84: 302.67
A85: 45998 | B85: T | C85: -302.67
A86: 45996 | B86: F | C86: 431.36
A87: 46003 | B87: F | C87: 332.49
A88: 46004 | B88: T | C88: -25.14
...

Sheet ABASTO Y CHARCUTERIA WILMARY
A1: CLIENTE | B1: ABASTO Y CHARCUTERIA WILMARY
A2: NOMBRE | B2: ANA CONTRERAS
A3: TOTALES | C3: =SUM(C$4:C$1048576) -> 54.72 | D3: =SUM(D$4:D$1048576) -> 0 | E3: =SUM(E$5:E$1048576) -> 0 | F3: =SUM(F$5:F$1048576) -> 0 | G3: =SUM(G$5:G$1048576) -> 0
A4: FECHA | B4: F- E- T- | C4: DEUDA Y ABONOS | D4: VACIO 1/4 | E4: VACIO 350 | F4: VACIO 1.25 | G4: RETECION
A5: 45932 | B5: F | C5: 25.45
A6: 45932 | B6: F | C6: 29.18
A7: 45939 | B7: T | C7: -54.63
A8: 45939 | B8: F | C8: 25.98
A9: 45939 | B9: F | C9: 21.27
A10: 45946 | B10: T | C10: -46.7
A11: 45946 | B11: F | C11: 16.38
A12: 45946 | B12: F | C12: 34.29
A13: 45952 | B13: T | C13: -50.67
A14: 45953 | B14: F | C14: 25.98
A15: 45953 | B15: F | C15: 25.71
A16: 45959 | B16: T | C16: -52.24
... A44: 46051 | B44: F | C44: 54.72

Sheet ABASTO YUDERLI
A1: CLIENTE | B1: ABASTO YUDERLI
A2: NOMBRE
A3: TOTALES | C3: =SUM(C$4:C$1048576) -> 0.02 | D3: =SUM(D$4:D$1048576) -> 1 | E3: =SUM(E$5:E$1048576) -> 0 | F3: =SUM(F$5:F$1048576) -> 0 | G3: =SUM(G$5:G$1048576) -> 0
A4: FECHA | B4: F- E- T- | C4: DEUDA Y ABONOS | D4: VACIO 1/4 | E4: VACIO 350 | F4: VACIO 1.25 | G4: RETECION
A5: 45821 | B5: F | C5: 15.85 | D5: 1
A6: 45846 | B6: T | C6: -15.84
A7: 45849 | B7: F | C7: 7.5
A8: 45849 | B8: F | C8: 16.56 | D8: -1
A9: 45856 | B9: E | C9: -24.1
A10: 45856 | B10: F | C10: 23.35
A11: 45856 | B11: F | C11: =82.62+0.3 -> 82.92
A12: 45862 | B12: T | C12: -10.25
A13: 45863 | B13: E | C13: -80.64
A14: 45863 | B14: F | C14: 7.5
A15: 45863 | B15: F | C15: 4.25
A16: 45863 | B16: F | C16: 12.2
A17: 45870 | B17: E | C17: -39.29
A18: 45870 | B18: F | C18: 40.5
A19: 45884 | B19: E | C19: -29.03
A20: 45891 | B20: E | C20: -11.48
A21: 45919 | B21: F | C21: 15.85
A22: 45926 | B22: E | C22: -12.9
A23: 45926 | B23: F | C23: 16.62
A24: 45926 | B24: F | C24: 20.8 | D24: 1
A25: 45933 | B25: E | C25: -30.77
A26: 45940 | B26: E | C26: -9.58
A27: 45940 | B27: F | C27: 11.7
A28: 45940 | B28: F | C28: 14.6
A29: 45954 | B29: F | C29: 16.38
A30: 45954 | B30: F | C30: 43.06
A31: 45954 | B31: E | C31: -22.22
A32: 45961 | B32: E | C32: -14.81
A33: 45975 | B33: E | C33: -24.28
A34: 45996 | B34: E | C34: -24.43

Sheet ABASTO ZORANNY
A1: CLIENTE | B1: ABASTO ZORANNY
A2: NOMBRE | B2: ZORAIDA
A3: TOTALES | C3: =SUM(C$4:C$1048576) -> 0 | D3: =SUM(D$4:D$1048576) -> 0 | E3: =SUM(E$5:E$1048576) -> 0 | F3: =SUM(F$5:F$1048576) -> 0 | G3: =SUM(G$5:G$1048576) -> 0
A4: FECHA | B4: F- E- T- | C4: DEUDA Y ABONOS | D4: VACIO 1/4 | E4: VACIO 350 | F4: VACIO 1.25 | G4: RETECION
A5: 45814 | B5: F | C5: 23.42
A6: 45826 | B6: T | C6: -23.42
A7: 45826 | B7: F | C7: 27.18
A8: 45832 | B8: T | C8: -27.14
A9: 45833 | B9: F | C9: 14.44
A10: 45833 | B10: F | C10: 27.41
A11: 45840 | B11: T | C11: -41.74
A12: 45840 | B12: E | C12: -0.15
A13: 45840 | B13: F | C13: 4.6
A14: 45840 | B14: F | C14: 9.27
A15: 45842 | B15: T | C15: -13.87
A16: 45854 | B16: F | C16: 31.22
... A76: 46050 | B76: T | C76: -27.21

Sheet ALAS COMPAS
A1: CLIENTE | B1: ALAS COMPRAS
A2: NOMBRE | B2: ELICEO GARCIA
A3: TOTALES | C3: =SUM(C$4:C$1048576) -> 541.04 | D3: =SUM(D$4:D$1048576) -> 0 | E3: =SUM(E$5:E$1048576) -> 0 | F3: =SUM(F$5:F$1048576) -> 0 | G3: =SUM(G$5:G$1048576) -> 0
A4: FECHA | B4: F- E- T- | C4: DEUDA Y ABONOS | D4: VACIO 1/4 | E4: VACIO 350 | F4: VACIO 1.25 | G4: RETECION
A5: 45820 | B5: F | C5: 60.87
A6: 45820 | B6: F | C6: 435.5
A7: 45820 | B7: F | C7: 12.32
A8: 45831 | B8: T | C8: -508.68
A9: 45832 | B9: T | C9: -1.38
A10: 45834 | B10: F | C10: 15
A11: 45834 | B11: F | C11: 548.14
A12: 45834 | B12: F | C12: 6.69
A13: 45846 | B13: T | C13: -569.83
A14: 45846 | B14: F | C14: 123.31
A15: 45846 | B15: F | C15: 600.26
A16: 45846 | B16: F | C16: 12.9
... A19: 45869 | B19: F | C19: 88.63
A20: 45869 | B20: F | C20: 16.47 | I20: WILLI
A21: 45873 | B21: T | C21: -182.4
A22: 45876 | B22: F | C22: 43.33
A23: 45876 | B23: F | C23: 106.8
A24: 45887 | B24: T | C24: -261.92
A25: 45890 | B25: F | C25: 75.85
A26: 45890 | B26: F | C26: 112.27
A27: 45890 | B27: F | C27: 13.38
A28: 45893 | B28: T | C28: -98.67
A29: 45898 | B29: F | C29: 23.65
A30: 45898 | B30: F | C30: 45.54
A31: 45908 | B31: T | C31: -163.96
A32: 45911 | B32: F | C32: 29.52
... A68: 46052 | B68: T | C68: -239.66

Sheet ALVARO RINCON
A1: CLIENTE | B1: ALVARO RINCON
A2: NOMBRE
A3: TOTALES | C3: =SUM(C$4:C$1048576) -> 0 | D3: =SUM(D$4:D$1048576) -> 0 | E3: =SUM(E$5:E$1048576) -> 0 | F3: =SUM(F$5:F$1048576) -> 0 | G3: =SUM(G$5:G$1048576) -> 0
A4: FECHA | B4: F- E- T- | C4: DEUDA Y ABONOS | D4: VACIO 1/4 | E4: VACIO 350 | F4: VACIO 1.25 | G4: RETECION
A5: - | B5: F
B6: F
B7: T

Sheet ALEJANDRA NIETO
A1: CLIENTE | B1: ALEJANDRA NIETO
A2: NOMBRE
A3: TOTALES | C3: =SUM(C$4:C$1048576) -> -2.21 | D3: =SUM(D$4:D$1048576) -> 0 | E3: =SUM(E$5:E$1048576) -> 0 | F3: =SUM(F$5:F$1048576) -> 0 | G3: =SUM(G$5:G$1048576) -> 0
A4: FECHA | B4: F- E- T- | C4: DEUDA Y ABONOS | D4: VACIO 1/4 | E4: VACIO 350 | F4: VACIO 1.25 | G4: RETECION
A5: 45814 | B5: F | C5: 21
A6: 45825 | B6: E | C6: -21
A7: 45825 | B7: F | C7: 141.16
A8: 45834 | B8: E | C8: -141.19
A9: 45834 | B9: F | C9: 25.69
A10: 45834 | B10: F | C10: 101.86
A11: 45853 | B11: F | C11: 93.08
A12: 45854 | B12: E | C12: -100
A13: 45877 | B13: E | C13: -120.55
A14: 45877 | B14: F | C14: 15.84
A15: 45877 | B15: F | C15: 119.05
A16: 45896 | B16: E | C16: -134.16
... A34: 46055 | B34: T | C34: -8

Sheet AMALUBE
A1: CLIENTE | B1: AMALUBE
A2: NOMBRE
A3: TOTALES | C3: =SUM(C$4:C$1048576) -> 33.85 | D3: =SUM(D$4:D$1048576) -> 0 | E3: =SUM(E$5:E$1048576) -> 0 | F3: =SUM(F$5:F$1048576) -> 0 | G3: =SUM(G$5:G$1048576) -> 0
A4: FECHA | B4: F- E- T- | C4: DEUDA Y ABONOS | D4: VACIO 1/4 | E4: VACIO 350 | F4: VACIO 1.25 | G4: RETECION
A5: 45826 | B5: F | C5: 25.69
A6: 45826 | B6: F | C6: 199.04
A7: 45841 | B7: T | C7: -174.73
A8: 45846 | B8: T | C8: -50
A9: 45847 | B9: F | C9: 25.69
A10: 45847 | B10: F | C10: 292.09
A11: 45847 | B11: F | C11: 47.6
A12: 45861 | B12: T | C12: -165.38
A13: 45862 | B13: T | C13: -79.39
A14: 45863 | B14: T | C14: -90
A15: 45868 | B15: T | C15: -25
A16: 45868 | B16: F | C16: 20
... A51: 45980 | B51: T | C51: -163.91
A52: 45980 | B52: F | C52: 206.74 | D52: 1
A53: 45986 | B53: T | C53: -207.18
A54: 45987 | B54: F | C54: 150.59
A55: 45998 | B55: T | C55: -148.8
A56: 46001 | B56: F | C56: 123.12 | D56: -1
A57: 46009 | B57: T | C57: -123.59
A58: 46014 | B58: F | C58: 240.74
A59: 46020 | B59: T | C59: -118.66
A60: 46020 | B60: T | C60: -101.71
A61: 46020 | B61: T | C61: -20.38
A62: 46029 | B62: F | C62: 98.76
A63: 46031 | B63: T | C63: -98.76
A64: 46036 | B64: F | C64: 237.06
A65: 46042 | B65: T | C65: -237.06
A66: 46043 | B66: F | C66: 54.7
A67: 46048 | B67: T | C67: -54.7
A68: 46050 | B68: F | C68: 32.3 | L68: =38450.32/355.5528 -> 108.14236
L69: =+L68-56.25 -> 51.892363
L70: =+L69*355.5528 -> 18450.475
L73: =54.7*355.5528 -> 19448.738
L74: =38450.32-L73 -> 19001.582

Sheet AMEZQUITA BODEGON
A1: CLIENTE | B1: AMEZQUITA BODEGON
A2: NOMBRE
A3: TOTALES | C3: =SUM(C$4:C$1048576) -> 335.58 | D3: =SUM(D$4:D$1048576) -> 1 | E3: =SUM(E$5:E$1048576) -> 0 | F3: =SUM(F$5:F$1048576) -> 0 | G3: =SUM(G$5:G$1048576) -> 0
A4: FECHA | B4: F- E- T- | C4: DEUDA Y ABONOS | D4: VACIO 1/4 | E4: VACIO 350 | F4: VACIO 1.25 | G4: RETECION
A5: 45826 | B5: F | C5: 25.69
A6: 45826 | B6: F | C6: 199.04
A7: 45841 | B7: T | C7: -174.73
A8: 45846 | B8: T | C8: -50
A9: 45847 | B9: F | C9: 25.69
A10: 45847 | B10: F | C10: 292.09
A11: 45847 | B11: F | C11: 47.6
A12: 45861 | B12: T | C12: -165.38
A13: 45862 | B13: T | C13: -79.39
A14: 45863 | B14: T | C14: -90
A15: 45868 | B15: T | C15: -25
A16: 45868 | B16: F | C16: 20
... A51: 45980 | B51: T | C51: -163.91
A52: 45980 | B52: F | C52: 206.74 | D52: 1
A53: 45986 | B53: T | C53: -207.18
A54: 45998 | B54: T | C54: -267.62
A55: 45996 | B55: F | C55: 265.59 | D55: 1
A56: 46003 | B56: F | C56: 17.34 | D56: -1
A57: 46010 | B57: T | C57: -17.34
A58: 46010 | B58: F | C58: 22.5
A59: 46017 | B59: T | C59: -22.5
A60: 46017 | B60: F | C60: 303.97
A61: 46024 | B61: T | C61: -303.97
A62: 46031 | B62: F | C62: 63.74
A63: 46038 | B63: T | C63: -61.95
A64: 46038 | B64: F | C64: 51.76
A65: 46044 | B65: T | C65: -51.76
A66: 46052 | B66: F | C66: 335.58

Sheet ANDERZON POLAR
A1: CLIENTE | B1: ANDERZON POLAR
A2: NOMBRE | M2: =4319.86-100 -> 4219.86
A3: TOTALES | C3: =SUM(C$4:C$1048576) -> 0.25 | D3: =SUM(D$4:D$1048576) -> 0 | E3: =SUM(E$5:E$1048576) -> 0 | F3: =SUM(F$5:F$1048576) -> 0 | G3: =SUM(G$5:G$1048576) -> 0
A4: FECHA | B4: F- E- T- | C4: DEUDA Y ABONOS | D4: VACIO 1/4 | E4: VACIO 350 | F4: VACIO 1.25 | G4: RETECION
A5: 45912 | B5: F | C5: 22.12
A6: 45958 | B6: V | C6: -108.75
A7: 45961 | B7: T | C7: -22.12
A8: 45961 | B8: F | C8: 115 | D8: 5
A9: 45964 | B9: T | C9: -6
A10: 46036 | B10: v | D10: -5

Sheet ANDERZON RODRIGUEZ
A1: CLIENTE | B1: ANDERZON RODRIGUEZ
A2: NOMBRE | M2: =4319.86-100 -> 4219.86
A3: TOTALES | C3: =SUM(C$4:C$1048576) -> 127.18 | D3: =SUM(D$4:D$1048576) -> 0 | E3: =SUM(E$5:E$1048576) -> -1 | F3: =SUM(F$5:F$1048576) -> -2 | G3: =SUM(G$5:G$1048576) -> 0
A4: FECHA | B4: F- E- T- | C4: DEUDA Y ABONOS | D4: VACIO 1/4 | E4: VACIO 350 | F4: VACIO 1.25 | G4: RETECION
A5: 45815 | B5: F | C5: 23.55 | D5: 1
A6: 45815 | B6: F | C6: 44.6
A7: 45815 | B7: F | C7: 9.15
A8: 45824 | B8: T | C8: -77.78
A9: 45826 | B9: F | C9: 71.12
A10: 45833 | B10: F | C10: 55.35
A11: 45833 | B11: F | C11: 5.66
A12: 45840 | B12: T | C12: -61
A13: 45840 | B13: T | C13: -71.12
A14: 45840 | B14: F | C14: 15.85
A15: 45840 | B15: F | C15: 63.95
A16: 45847 | B16: F | C16: 46.11
A17: 45854 | B17: T | C17: -11.23
... A24: 45863 | B24: T | C24: -17.28
A25: 45868 | B25: F | C25: 15.85 | D25: -1
A26: 45868 | B26: F | C26: 58.62
A27: 45869 | B27: T | C27: -9.72
A28: 45869 | B28: F | C28: 13.68
A29: 45876 | B29: T | C29: -40.16
A30: 45876 | B30: T | C30: -61.99
A31: 45876 | B31: F | C31: 4.5
A32: 45876 | B32: F | C32: 45.58
A33: 45880 | B33: T | C33: -26.16
A34: 45883 | B34: T | C34: -37.18
A35: 45883 | B35: F | C35: 18.6
A36: 45883 | B36: F | C36: 39.53
A37: 45887 | B37: T | C37: -13.55
... A110: 46009 | B110: T | C110: -25.04
A111: 46009 | B111: F | C111: 139.92 | E111: -1
A112: 46013 | B112: T | C112: -15.77
A113: 46014 | B113: T | C113: -10.4
A114: 46017 | B114: T | C114: -23.8
A115: 46020 | B115: T | C115: -27.12
A116: 46024 | B116: T | C116: -19.91
A117: 46024 | B117: T | C117: -21.57
A118: 46030 | B118: T | C118: -6.23
...

Sheet ANDREA URDANETA
A1: CLIENTE | B1: ANDREA URDANETA
A2: NOMBRE
A3: TOTALES | C3: =SUM(C$4:C$1048576) -> 368.59 | D3: =SUM(D$4:D$1048576) -> 0 | E3: =SUM(E$5:E$1048576) -> 0 | F3: =SUM(F$5:F$1048576) -> 0 | G3: =SUM(G$5:G$1048576) -> 0
A4: FECHA | B4: F- E- T- | C4: DEUDA Y ABONOS | D4: VACIO 1/4 | E4: VACIO 350 | F4: VACIO 1.25 | G4: RETECION
A5: 45875 | B5: F | C5: 18.84
A6: 45875 | B6: F | C6: 105.43
A7: 45875 | B7: F | C7: 18.3
A8: 45876 | B8: T | C8: -65
A9: 45880 | B9: T | C9: -50
A10: 45882 | B10: T | C10: -27.85
A11: 45883 | B11: T | C11: -74.36
A12: 45882 | B12: F | C12: 9.6
A13: 45882 | B13: F | C13: 97.81
A14: 45882 | B14: F | C14: 59.29
A15: 45884 | B15: T | C15: -92.33
A16: 45889 | B16: F | C16: 40.78
... A109: 46052 | B109: F | C109: 87

Sheet APRICOT
A1: CLIENTE | B1: APRICOT
A2: NOMBRE
A3: TOTALES | C3: =SUM(C$4:C$1048576) -> 440.72 | D3: =SUM(D$4:D$1048576) -> 12 | E3: =SUM(E$5:E$1048576) -> 0 | F3: =SUM(F$5:F$1048576) -> 0 | G3: =SUM(G$5:G$1048576) -> 0
A4: FECHA | B4: F- E- T- | C4: DEUDA Y ABONOS | D4: VACIO 1/4 | E4: VACIO 350 | F4: VACIO 1.25 | G4: RETECION
A5: 45828 | B5: F | C5: 123.41
A6: 45848 | B6: T | C6: -89
A7: 45856 | B7: T | C7: -34.41
A8: 45856 | B8: F | C8: 44.2
A9: 45873 | B9: T | C9: -19.4
A10: 45875 | B10: T | C10: -15.6
A11: 45877 | B11: F | C11: 53.95
A12: 45880 | B12: T | C12: -13.67
A13: 45896 | B13: T | C13: -49.01
A14: 45897 | B14: F | C14: 33.8
A15: 45908 | B15: F | C15: 208 | D15: 10
A16: 45911 | B16: T | C16: -33.8
A17: 45912 | B17: F | C17: 342 | D17: =12-10 -> 2
A18: 45912 | B18: F | C18: 21.7
A19: 45918 | B19: T | C19: -104
A20: 45919 | B20: T | C20: -38
A21: 45922 | B21: T | C21: -363.69
A22: 45923 | B22: T | C22: -104.9
A23: 45923 | B23: F | C23: 322.8
A24: 45923 | B24: F | C24: 7.5
A25: 45931 | B25: T | C25: -62.36
A26: 45932 | B26: T | C26: -80
A27: 45933 | B27: F | C27: 41.5
A28: 45933 | B28: F | C28: 21.7
A29: 45940 | B29: T | C29: -49.5
... A39: 46045 | B39: F | C39: 440

Sheet AURA VIVAS
A1: CLIENTE | B1: AURA VIVAS
A2: NOMBRE
A3: TOTALES | C3: =SUM(C$4:C$1048576) -> -0.002 | D3: =SUM(D$4:D$1048576) -> 0 | E3: =SUM(E$5:E$1048576) -> 0 | F3: =SUM(F$5:F$1048576) -> 0 | G3: =SUM(G$5:G$1048576) -> 0
A4: FECHA | B4: F- E- T- | C4: DEUDA Y ABONOS | D4: VACIO 1/4 | E4: VACIO 350 | F4: VACIO 1.25 | G4: RETECION
A5: 45912 | B5: T | C5: -49.98
A6: 45912 | B6: F | C6: 7.5
A7: 45912 | B7: F | C7: 42.48
A8: 45920 | B8: F | C8: 7.5
A9: 45920 | B9: F | C9: 68.94
A10: 45922 | B10: T | C10: -76.44
A11: 45933 | B11: F | C11: 79.28
A12: 45938 | B12: T | C12: -40.99
A13: 45940 | B13: F | C13: 52.368
A14: 45947 | B14: E | C14: -52.69
A15: 45950 | B15: T | C15: -37.97

Sheet AVENTURA INFLABLE
A1: CLIENTE | B1: AVENTURA INFLABLE
A2: NOMBRE
A3: TOTALES | C3: =SUM(C$4:C$1048576) -> 1.9539925e-13 | D3: =SUM(D$4:D$1048576) -> 2 | E3: =SUM(E$5:E$1048576) -> 0 | F3: =SUM(F$5:F$1048576) -> 0 | G3: =SUM(G$5:G$1048576) -> 0
A4: FECHA | B4: F- E- T- | C4: DEUDA Y ABONOS | D4: VACIO 1/4 | E4: VACIO 350 | F4: VACIO 1.25 | G4: RETECION
A5: 46017 | B5: F | C5: 709.9 | D5: 2
A6: 46020 | B6: T | C6: -709.88
A7: 46020 | B7: F | C7: 719.44
A8: 46021 | B8: F | C8: 113.23
A9: 46022 | B9: T | C9: -832.67
A10: 46030 | B10: F | C10: 1938.84
A11: 46031 | B11: T | C11: -1014.17
A12: 46037 | B12: F | C12: 773.4
A13: 46044 | B13: T | C13: -924.67
A14: 46045 | B14: T | C14: -767.51
A15: 46052 | B15: T | C15: -5.91

Sheet BARBERIA SPARTA
A1: CLIENTE | B1: BARBERIA SPARTA
A2: NOMBRE
A3: TOTALES | C3: =SUM(C$4:C$1048576) -> 0 | D3: =SUM(D$4:D$1048576) -> 0 | E3: =SUM(E$5:E$1048576) -> 0 | F3: =SUM(F$5:F$1048576) -> 0 | G3: =SUM(G$5:G$1048576) -> 0
A4: FECHA | B4: F- E- T- | C4: DEUDA Y ABONOS | D4: VACIO 1/4 | E4: VACIO 350 | F4: VACIO 1.25 | G4: RETECION
A5: 46042 | B5: T | C5: -39.31
A6: 46042 | B6: F | C6: 39.31

Sheet BAKAI MACHIRI
A1: CLIENTE | B1: BAKAI MACHIRI
A2: NOMBRE
A3: TOTALES | C3: =SUM(C$4:C$1048576) -> 71.28 | D3: =SUM(D$4:D$1048576) -> 0 | E3: =SUM(E$5:E$1048576) -> 0 | F3: =SUM(F$5:F$1048576) -> 0 | G3: =SUM(G$5:G$1048576) -> 44.73
A4: FECHA | B4: F- E- T- | C4: DEUDA Y ABONOS | D4: VACIO 1/4 | E4: VACIO 350 | F4: VACIO 1.25 | G4: RETECION
A5: 45819 | B5: F | C5: =39.2-G5 -> 35.15 | G5: 4.05
A6: 45819 | B6: F | C6: 27.96
A7: 45819 | B7: F | C7: 19.88
A8: 45827 | B8: T | C8: -83.2 | G8: -4.05
A9: 45834 | B9: F | C9: 59.85
A10: 45834 | B10: F | C10: 40.68
A11: 45834 | B11: F | C11: 20.8
A12: 45853 | B12: T | C12: -121.32
A13: 45854 | B13: F | C13: =59.55-G13 -> 51.81 | G13: 7.74
A14: 45854 | B14: F | C14: 43.28
A15: 45854 | B15: F | C15: 40.7
A16: 45862 | B16: R | G16: -7.74
A17: 45866 | B17: T | C17: -129.99
A18: 45869 | B18: F | C18: =52.68-G18 -> 47.24 | G18: 5.44
A19: 45869 | B19: F | C19: 36.57
A20: 45880 | B20: T | C20: -91.39 | G20: -5.44
A21: 45881 | B21: F | C21: =67.28-G21 -> 62.14 | G21: 5.14
A22: 45881 | B22: F | C22: =86.74-G22 -> 78.85 | G22: 7.89
A23: 45890 | B23: R | G23: -13.03
A24: 45894 | B24: T | C24: -138.09
A25: 45897 | B25: F | C25: =77.28-G25 -> 69.29 | G25: 7.99
A26: 45897 | B26: F | C26: =37.05-G26 -> 33.23 | G26: 3.82
A27: 45897 | B27: F | C27: 63.9
A28: 45903 | B28: T | C28: -166.42
A29: 45904 | B29: F | C29: =36.6-G29 -> 32.82 | G29: 3.78
A30: 45904 | B30: F | C30: =134.74-G30 -> 123.7 | G30: 11.04
A31: 45904 | B31: F | C31: 33.16
A32: 45917 | B32: T | C32: -154.99
A33: 45918 | B33: F | C33: =44.25-G33 -> 39.68 | G33: 4.57
A34: 45918 | B34: F | C34: =130.82-G34 -> 118.74 | G34: 12.08
A35: 45918 | B35: F | C35: 9.96
A36: 45925 | B36: F | C36: =46.68-G36 -> 41.86 | G36: 4.82
A37: 45925 | B37: F | C37: =115.5-G37 -> 105 | G37: 10.5
A38: 45925 | B38: F | C38: 9.96
A39: 45930 | B39: T | C39: -34.69
A40: 45930 | B40: T | C40: -203.98
...

Sheet BELKIS MONSALVE
A1: CLIENTE | B1: BELKIS MONSALVE
A2: NOMBRE
A3: TOTALES | C3: =SUM(C$4:C$1048576) -> 0 | D3: =SUM(D$4:D$1048576) -> 0 | E3: =SUM(E$5:E$1048576) -> 0 | F3: =SUM(F$5:F$1048576) -> 0 | G3: =SUM(G$5:G$1048576) -> 0
A4: FECHA | B4: F- E- T- | C4: DEUDA Y ABONOS | D4: VACIO 1/4 | E4: VACIO 350 | F4: VACIO 1.25 | G4: RETECION
B5: F
B6: F
B7: F
B8: T

Sheet BOD ALTOS PARAMILLO
A1: 3.64 | B1: BOD ALTOS PARAMILLO
A2: NOMBRE | B2: CIRA PERDOMO
A3: TOTALES | C3: =SUM(C$4:C$1048576) -> -0.02 | D3: =SUM(D$4:D$1048576) -> 0 | E3: =SUM(E$5:E$1048576) -> 0 | F3: =SUM(F$5:F$1048576) -> 0 | G3: =SUM(G$5:G$1048576) -> 0
A4: FECHA | B4: F- E- T- | C4: DEUDA Y ABONOS | D4: VACIO 1/4 | E4: VACIO 350 | F4: VACIO 1.25 | G4: RETECION
A5: 45888 | B5: F | C5: 20.8
A6: 45888 | B6: F | C6: 5
A7: 45902 | B7: F | C7: 4.5
A8: 45902 | B8: F | C8: 12.1
A9: 45909 | B9: E | C9: -16.61
A10: 45929 | B10: T | C10: -25.79
A11: 45958 | B11: T | C11: -44
A12: 45958 | B12: F | C12: 26.7
A13: 45958 | B13: F | C13: 4.6
A14: 45958 | B14: F | C14: 12.68

Sheet BOD MARBELYS ROA
A1: CLIENTE | B1: BOD MARBELYS ROA
A2: NOMBRE | B2: MARBELYS ROA
A3: TOTALES | C3: =SUM(C$4:C$1048576) -> 0.01 | D3: =SUM(D$4:D$1048576) -> 0 | E3: =SUM(E$5:E$1048576) -> 0 | F3: =SUM(F$5:F$1048576) -> 0 | G3: =SUM(G$5:G$1048576) -> 0
A4: FECHA | B4: F- E- T- | C4: DEUDA Y ABONOS | D4: VACIO 1/4 | E4: VACIO 350 | F4: VACIO 1.25 | G4: RETECION
A5: 45813 | B5: F | C5: 28.19
A6: 45817 | B6: T | C6: -28.19
A7: 45818 | B7: F | C7: 15.85
A8: 45820 | B8: T | C8: -15.84
A9: 45825 | B9: T | C9: -17.8
A10: 45825 | B10: F | C10: 7.8
A11: 45825 | B11: F | C11: 10
A12: 45832 | B12: F | C12: 10
A13: 45833 | B13: T | C13: -10
A14: 45839 | B14: T | C14: -19.04
A15: 45839 | B15: F | C15: 19.04
A16: 45846 | B16: T | C16: -46.65
... A29: 46056 | B29: F | C29: 17.28

Sheet BOD SOLMAR PINTO
A1: CLIENTE | B1: BOD SOLMAR PINTO
A2: NOMBRE
A3: TOTALES | C3: =SUM(C$4:C$1048576) -> 211.19 | D3: =SUM(D$4:D$1048576) -> 1 | E3: =SUM(E$5:E$1048576) -> 0 | F3: =SUM(F$5:F$1048576) -> 0 | G3: =SUM(G$5:G$1048576) -> 0
A4: FECHA | B4: F- E- T- | C4: DEUDA Y ABONOS | D4: VACIO 1/4 | E4: VACIO 350 | F4: VACIO 1.25 | G4: RETECION
A5: 45814 | B5: F | C5: 15.85
A6: 45814 | B6: F | C6: 85.99
A7: 45825 | B7: T | C7: -46.99
A8: 45841 | B8: T | C8: -55.95
A9: 45841 | B9: F | C9: 41.6
A10: 45841 | B10: F | C10: 15.85
A11: 45847 | B11: T | C11: -57.45
A12: 45848 | B12: F | C12: 62.4
A13: 45848 | B13: F | C13: 20.34
A14: 45855 | B14: T | C14: -9.54
A15: 45855 | B15: T | C15: -34.24
A16: 45855 | B16: T | C16: -38.97
... A27: 45873 | B27: T | C27: -16.34
A28: 45876 | B28: F | C28: 83.2 | D28: 1
A29: 45890 | B29: T | C29: -74.96
A30: 45890 | B30: T | C30: -24.11
A31: 45890 | B31: F | C31: 41.6
A32: 45890 | B32: F | C32: 25.69
A33: 45898 | B33: F | C33: 62.4
A34: 45898 | B34: F | C34: 9.84
A35: 45898 | B35: F | C35: 13.4
A36: 45903 | B36: T | C36: -23.77
A37: 45903 | B37: T | C37: -36.13
A38: 45903 | B38: T | C38: -7.21
A39: 45903 | B39: T | C39: -85.64
A40: 45904 | B40: F | C40: 62.4
... A94: 46051 | B94: T | C94: 155.12

Sheet BOD TOICO CLEIBER
A1: CLIENTE | B1: BOD TOICO CLEIBER
A2: NOMBRE | B2: CLEIBER ANDRADE
A3: TOTALES | C3: =SUM(C$4:C$1048576) -> 3.5527137e-14 | D3: =SUM(D$4:D$1048576) -> 0 | E3: =SUM(E$5:E$1048576) -> 0 | F3: =SUM(F$5:F$1048576) -> 0 | G3: =SUM(G$5:G$1048576) -> 0
A4: FECHA | B4: F- E- T- | C4: DEUDA Y ABONOS | D4: VACIO 1/4 | E4: VACIO 350 | F4: VACIO 1.25 | G4: RETECION
A5: 45813 | B5: F | C5: 7.8
A6: 45813 | B6: F | C6: 154.51
A7: 45818 | B7: F | C7: 17.54
A8: 45818 | B8: F | C8: 106.99
A9: 45818 | B9: F | C9: 13.76
A10: 45820 | B10: T | C10: -162.32
A11: 45825 | B11: T | C11: -139.36
A12: 45825 | B12: F | C12: 28.69
A13: 45825 | B13: F | C13: 57.48
A14: 45825 | B14: F | C14: 2.74
A15: 45832 | B15: T | C15: -88.89
A16: 45832 | B16: F | C16: 23.65
... A111: 46055 | B111: T | C111: -27.3

Sheet BOD TOICO OSMAR
A1: CLIENTE | B1: BOD TOICO OSMAR
A2: NOMBRE | B2: OSMAR SUAREZ
A3: TOTALES | C3: =SUM(C$4:C$1048576) -> -0.057 | D3: =SUM(D$4:D$1048576) -> 1 | E3: =SUM(E$5:E$1048576) -> 0 | F3: =SUM(F$5:F$1048576) -> 0 | G3: =SUM(G$5:G$1048576) -> 0
A4: FECHA | B4: F- E- T- | C4: DEUDA Y ABONOS | D4: VACIO 1/4 | E4: VACIO 350 | F4: VACIO 1.25 | G4: RETECION
A5: 45813 | B5: F | C5: 7.8
A6: 45813 | B6: F | C6: 102.63
A7: 45817 | B7: T | C7: -83.8
A8: 45818 | B8: F | C8: 20.8
A9: 45818 | B9: F | C9: 53.45
A10: 45820 | B10: T | C10: -19.93
A11: 45826 | B11: T | C11: -19.45
A12: 45827 | B12: T | C12: -19.28
A13: 45835 | B13: T | C13: -18.72
A14: 45835 | B14: T | C14: -18.72
A15: 45838 | B15: T | C15: -7.13
A16: 45839 | B16: F | C16: 33.19
... A33: 45881 | B33: E | C33: -1.29
A34: 45881 | B34: F | C34: 15.85 | D34: 1
A35: 45881 | B35: F | C35: 77.45
A36: 45890 | B36: T | C36: -17.93
A37: 45891 | B37: T | C37: -19.53
A38: 45895 | B38: T | C38: -55.82
A39: 45895 | B39: F | C39: 19.46
A40: 45895 | B40: F | C40: 57.48
A41: 45895 | B41: F | C41: 10.46
A42: 45909 | B42: T | C42: -19.36
A43: 45911 | B43: T | C43: -30.31
A44: 45916 | B44: T | C44: -21.81
A45: 45916 | B45: T | C45: -23.83
A46: 45916 | B46: F | C46: 33.19
... A75: 46043 | B75: T | C75: -23.5

Sheet BODEGA DE ORO
A1: CLIENTE | B1: BODEGA DE ORO
A2: NOMBRE
A3: TOTALES | C3: =SUM(C$4:C$1048576) -> 240.943 | D3: =SUM(D$4:D$1048576) -> 0 | E3: =SUM(E$5:E$1048576) -> 0 | F3: =SUM(F$5:F$1048576) -> 0 | G3: =SUM(G$5:G$1048576) -> 0
A4: FECHA | B4: F- E- T- | C4: DEUDA Y ABONOS | D4: VACIO 1/4 | E4: VACIO 350 | F4: VACIO 1.25 | G4: RETECION
A5: 45819 | B5: F | C5: 9.84
A6: 45819 | B6: F | C6: 53.31
A7: 45831 | B7: T | C7: -63.21
A8: 45834 | B8: T | C8: -65.7
A9: 45833 | B9: F | C9: 36.8
A10: 45833 | B10: F | C10: 25.69
A11: 45833 | B11: F | C11: 3.21
A12: 45840 | B12: F | C12: 53.94
A13: 45840 | B13: F | C13: 18.4
A14: 45848 | B14: F | C14: 7.5
A15: 45848 | B15: F | C15: 23.49
A16: 45848 | B16: F | C16: 16.44
... A124: 46051 | B124: F | C124: 189.19

Sheet BODEGA DE CECI
A1: CLIENTE | B1: BODEGA DE CECI
A2: NOMBRE
A3: TOTALES | C3: =SUM(C$4:C$1048576) -> 0 | D3: =SUM(D$4:D$1048576) -> 0 | E3: =SUM(E$5:E$1048576) -> 0 | F3: =SUM(F$5:F$1048576) -> 0 | G3: =SUM(G$5:G$1048576) -> 0
A4: FECHA | B4: F- E- T- | C4: DEUDA Y ABONOS | D4: VACIO 1/4 | E4: VACIO 350 | F4: VACIO 1.25 | G4: RETECION
A5: 45848 | B5: F | C5: 58.69
A6: 45855 | B6: T | C6: -58.69

Sheet BODEGA EL ARBOLITO
A1: CLIENTE | B1: BODEGA EL ARBOLITO
A2: NOMBRE
A3: TOTALES | C3: =SUM(C$4:C$1048576) -> 96.43 | D3: =SUM(D$4:D$1048576) -> 0 | E3: =SUM(E$5:E$1048576) -> 0 | F3: =SUM(F$5:F$1048576) -> 0 | G3: =SUM(G$5:G$1048576) -> 0
A4: FECHA | B4: F- E- T- | C4: DEUDA Y ABONOS | D4: VACIO 1/4 | E4: VACIO 350 | F4: VACIO 1.25 | G4: RETECION
A5: 45869 | B5: F | C5: 20.8
A6: 45869 | B6: F | C6: 9.2
A7: 45883 | B7: E | C7: -30
A8: 45898 | B8: F | C8: 42.39
A9: 45904 | B9: E | C9: -42.41
A10: 45904 | B10: F | C10: 32.55
A11: 45911 | B11: E | C11: -32.58
A12: 45911 | B12: F | C12: 24.2
A13: 45920 | B13: E | C13: -24.22
A14: 45925 | B14: F | C14: 58.03
A15: 45932 | B15: E | C15: -57.96
A16: 45939 | B16: F | C16: 40.02
... A44: 46045 | B44: T | C44: -60

Sheet BODEGA EL GATO
A1: CLIENTE | B1: BODEGA EL GATO
A2: NOMBRE | B2: YOLYMAR DELGADO
A3: TOTALES | C3: =SUM(C$4:C$1048576) -> 13.42 | D3: =SUM(D$4:D$1048576) -> 0 | E3: =SUM(E$5:E$1048576) -> 0 | F3: =SUM(F$5:F$1048576) -> 0 | G3: =SUM(G$5:G$1048576) -> 0
A4: FECHA | B4: F- E- T- | C4: DEUDA Y ABONOS | D4: VACIO 1/4 | E4: VACIO 350 | F4: VACIO 1.25 | G4: RETECION
A5: 45910 | B5: F | C5: 44.28
A6: 45917 | B6: T | C6: -44.28
A7: 45917 | B7: F | C7: 15
A8: 45917 | B8: F | C8: 51.25
A9: 45924 | B9: E | C9: -66.15
A10: 45924 | B10: F | C10: 12.4
A11: 45924 | B11: F | C11: 12.01
A12: 45932 | B12: T | C12: -24.52
A13: 45938 | B13: F | C13: 12.1
A14: 45938 | B14: F | C14: 33.63
A15: 45945 | B15: E | C15: -45.73
A16: 45967 | B16: F | C16: 19.6
... A30: 46044 | B30: F | C30: 13.45

Sheet BODEGA EL SOL
A1: CLIENTE | B1: BODEGA EL SOL
A2: NOMBRE | B2: ROSA VALERO
A3: TOTALES | C3: =SUM(C$4:C$1048576) -> 29.52 | D3: =SUM(D$4:D$1048576) -> 0 | E3: =SUM(E$5:E$1048576) -> 0 | F3: =SUM(F$5:F$1048576) -> 0 | G3: =SUM(G$5:G$1048576) -> 0
A4: FECHA | B4: F- E- T- | C4: DEUDA Y ABONOS | D4: VACIO 1/4 | E4: VACIO 350 | F4: VACIO 1.25 | G4: RETECION
A5: 45853 | B5: F | C5: 180
A6: 45853 | B6: F | C6: 9.2
A7: 45853 | B7: F | C7: 39.06
A8: 45861 | B8: T | C8: -46.5
A9: 45873 | B9: T | C9: -47.51
A10: 45873 | B10: T | C10: -21.38
A11: 45877 | B11: T | C11: -46.13
A12: 45881 | B12: E | C12: -47
A13: 45881 | B13: F | C13: 161.6
A14: 45882 | B14: T | C14: -7.59
A15: 45882 | B15: T | C15: -12.07
A16: 45887 | B16: T | C16: -73.05
... A33: 46049 | B33: F | C33: 29.52

Sheet BODEGA EXPRESS
A1: CLIENTE | B1: BODEGA EXPRESS
A2: NOMBRE | B2: GERMAN CALDERON
A3: TOTALES | C3: =SUM(C$4:C$1048576) -> 441.92 | D3: =SUM(D$4:D$1048576) -> 0 | E3: =SUM(E$5:E$1048576) -> 0 | F3: =SUM(F$5:F$1048576) -> -1 | G3: =SUM(G$5:G$1048576) -> 0
A4: FECHA | B4: F- E- T- | C4: DEUDA Y ABONOS | D4: VACIO 1/4 | E4: VACIO 350 | F4: VACIO 1.25 | G4: RETECION
A5: 45815 | B5: F | C5: 9.84
A6: 45815 | B6: F | C6: 93.84
A7: 45821 | B7: T | C7: -70
A8: 45821 | B8: F | C8: 41.54
A9: 45821 | B9: F | C9: 243.06
A10: 45827 | B10: T | C10: -269.92
A11: 45828 | B11: F | C11: 191.19
A12: 45842 | B12: T | C12: -212.56
A13: 45845 | B13: T | C13: -26.99
A14: 45842 | B14: F | C14: 15.85
A15: 45842 | B15: F | C15: 234.64
A16: 45849 | B16: F | C16: 15.85
... A31: 45884 | B31: T | C31: -350.46
A32: 45884 | B32: F | C32: 47.55 | D32: 2
A33: 45884 | B33: F | C33: 147.71
A34: 45884 | B34: F | C34: 5.93
A35: 45891 | B35: F | C35: 19.68
A36: 45891 | B36: F | C36: 174.32
A37: 45897 | B37: T | C37: -285
A38: 45898 | B38: F | C38: 9.84
A39: 45898 | B39: F | C39: 282.74
A40: 45905 | B40: T | C40: -372.77
A41: 45905 | B41: F | C41: 27.18 | D41: -1
A42: 45905 | B42: F | C42: 127.22
A43: 45905 | B43: F | C43: 8.76
A44: 45912 | B44: T | C44: -193.16
A45: 45912 | B45: F | C45: 40.7
A46: 45912 | B46: F | C46: 90.12
A47: 45912 | B47: F | C47: 126.82
A48: 45919 | B48: T | C48: -34.86
A49: 45919 | B49: F | C49: 34.9
A50: 45919 | B50: F | C50: 139.21
A51: 45919 | B51: F | C51: 19.68
A52: 45926 | B52: T | C52: -416.57
A53: 45926 | B53: F | C53: 40.69
... A56: 45926 | B56: F | C56: 23.62
...

Sheet BODEGA EL GUARO
A1: CLIENTE | B1: BODEGA EL GUARO
A2: NOMBRE | B2: SORANYL VILLAMIZAR
A3: TOTALES | C3: =SUM(C$4:C$1048576) -> -0.4 | D3: =SUM(D$4:D$1048576) -> 0 | E3: =SUM(E$5:E$1048576) -> 0 | F3: =SUM(F$5:F$1048576) -> 0 | G3: =SUM(G$5:G$1048576) -> 0
A4: FECHA | B4: F- E- T- | C4: DEUDA Y ABONOS | D4: VACIO 1/4 | E4: VACIO 350 | F4: VACIO 1.25 | G4: RETECION
A5: 45960 | B5: F | C5: 12.1
A6: 45960 | B6: F | C6: 50.52
A7: 45967 | B7: F | C7: 21.94
A8: 45968 | B8: F | C8: 44.04
A9: 45978 | B9: T | C9: -30
A10: 45992 | B10: T | C10: -67
A11: 45999 | B11: T | C11: -32

Sheet BODEGA DONITA
A1: CLIENTE | B1: BODEGA DONITA
A2: NOMBRE | B2: YUDY NINO
A3: TOTALES | C3: =SUM(C$4:C$1048576) -> -0.05 | D3: =SUM(D$4:D$1048576) -> 0 | E3: =SUM(E$5:E$1048576) -> 0 | F3: =SUM(F$5:F$1048576) -> 0 | G3: =SUM(G$5:G$1048576) -> 0
A4: FECHA | B4: F- E- T- | C4: DEUDA Y ABONOS | D4: VACIO 1/4 | E4: VACIO 350 | F4: VACIO 1.25 | G4: RETECION
A5: 45821 | B5: F | C5: 20.77
A6: 45828 | B6: T | C6: -15.85
A7: 45828 | B7: T | C7: -4.68
A8: 45828 | B8: F | C8: 43.33
A9: 45841 | B9: E | C9: -15.85
A10: 45841 | B10: E | C10: -27.75
A11: 45841 | B11: F | C11: 30.61
A12: 45848 | B12: E | C12: -30.62
A13: 45856 | B13: F | C13: 9.84
A14: 45876 | B14: T | C14: -9.84
A15: 45876 | B15: F | C15: 30.61
A16: 45882 | B16: T | C16: -30.61
... A54: 46013 | B54: T | C54: -51.26

Sheet BODEGA ESCALANTE
A1: CLIENTE | B1: BODEGA ESCALANTE
A2: NOMBRE | B2: MARIA BAUTISTA
A3: TOTALES | C3: =SUM(C$4:C$1048576) -> -1.2 | D3: =SUM(D$4:D$1048576) -> 0 | E3: =SUM(E$5:E$1048576) -> 0 | F3: =SUM(F$5:F$1048576) -> 0 | G3: =SUM(G$5:G$1048576) -> 0
A4: FECHA | B4: F- E- T- | C4: DEUDA Y ABONOS | D4: VACIO 1/4 | E4: VACIO 350 | F4: VACIO 1.25 | G4: RETECION
A5: 45835 | B5: F | C5: 12.1
A6: 45835 | B6: F | C6: 81.76
A7: 45842 | B7: T | C7: -93.86
A8: 45842 | B8: F | C8: 9.84
A9: 45842 | B9: F | C9: 91.14
A10: 45849 | B10: T | C10: -100.98
A11: 45849 | B11: F | C11: 7.5
A12: 45849 | B12: F | C12: 74.66
A13: 45855 | B13: T | C13: -82.16
A14: 45856 | B14: F | C14: 41.6
A15: 45856 | B15: F | C15: 15.85
A16: 45856 | B16: F | C16: 20.52
... A23: 45996 | B23: T | C23: -7.06

Sheet BODEGA LOS CHACAROS
A1: CLIENTE | B1: BODEGA LOS CHACAROS
A2: NOMBRE | B2: YANET
A3: TOTALES | C3: =SUM(C$4:C$1048576) -> 0 | D3: =SUM(D$4:D$1048576) -> 2 | E3: =SUM(E$5:E$1048576) -> 0 | F3: =SUM(F$5:F$1048576) -> 0 | G3: =SUM(G$5:G$1048576) -> 0
A4: FECHA | B4: F- E- T- | C4: DEUDA Y ABONOS | D4: VACIO 1/4 | E4: VACIO 350 | F4: VACIO 1.25 | G4: RETECION
A5: 45817 | B5: T | C5: -25.69
A6: 45815 | B6: F | C6: 25.69
A7: 45821 | B7: T | C7: -16.02
A8: 45821 | B8: F | C8: 15.85
A9: 45838 | B9: T | C9: -25.65
A10: 45835 | B10: F | C10: 25.69
A11: 45849 | B11: T | C11: -15.98
A12: 45849 | B12: F | C12: 15.85
A13: 45859 | B13: T | C13: -19.68
A14: 45860 | B14: F | C14: 19.68
A15: 45873 | B15: T | C15: -25.51
A16: 45870 | B16: F | C16: 25.69
... A56: 45979 | B56: T | C56: -450
A57: 45979 | B57: F | C57: 516.94 | D57: 1
A58: 45980 | B58: T | C58: -86.62
A59: 45989 | B59: T | C59: -445.4 | K59: PENDIENTE EL DEPACHO DE 24 PEPSI COLOCAR DESCUENTO 22.8
A60: 45989 | B60: F | C60: 445.4
A61: 45998 | B61: T | C61: -674.04
A62: 45996 | B62: F | C62: 674.06
A63: 45996 | B63: % | C63: -22.8
A64: 46000 | B64: F | C64: 274.8
A65: 46001 | B65: T | C65: -274.8
A66: 46010 | B66: T | C66: -436.92
A67: 46010 | B67: F | C67: 432.5 | D67: 1
A68: 46017 | B68: T | C68: -481.7
A69: 46017 | B69: F | C69: 475.65
A70: 46038 | B70: T | C70: -74.96
A71: 46038 | B71: F | C71: 110.45
A72: 46055 | B72: T | C72: -538.85
A73: 46052 | B73: F | C73: 538.86

Sheet BODEGA MARIA
A1: CLIENTE | B1: BODEGA MARIA
A2: NOMBRE | B2: JANCITO BELLO
A3: TOTALES | C3: =SUM(C$4:C$1048576) -> 0 | D3: =SUM(D$4:D$1048576) -> 0 | E3: =SUM(E$5:E$1048576) -> 0 | F3: =SUM(F$5:F$1048576) -> 0 | G3: =SUM(G$5:G$1048576) -> 0
A4: FECHA | B4: F- E- T- | C4: DEUDA Y ABONOS | D4: VACIO 1/4 | E4: VACIO 350 | F4: VACIO 1.25 | G4: RETECION
A5: 45917 | B5: T | C5: -55.51
A6: 45917 | B6: F | C6: 25.69
A7: 45917 | B7: F | C7: 29.82

Sheet BODEGA MARITZA
A1: CLIENTE | B1: BODEGA MARITZA
A2: NOMBRE | B2: ROJAS
A3: TOTALES | C3: =SUM(C$4:C$1048576) -> 166.64 | D3: =SUM(D$4:D$1048576) -> 0 | E3: =SUM(E$5:E$1048576) -> 0 | F3: =SUM(F$5:F$1048576) -> 0 | G3: =SUM(G$5:G$1048576) -> 0
A4: FECHA | B4: F- E- T- | C4: DEUDA Y ABONOS | D4: VACIO 1/4 | E4: VACIO 350 | F4: VACIO 1.25 | G4: RETECION
A5: 45833 | B5: F | C5: 32.64
A6: 45833 | B6: F | C6: 144.83
A7: 45839 | B7: T | C7: -143.41
A8: 45840 | B8: T | C8: -34.06
A9: 45840 | B9: F | C9: 19.68
A10: 45840 | B10: F | C10: 145.06
A11: 45846 | B11: T | C11: -164.74
A12: 45847 | B12: F | C12: 7.8
A13: 45847 | B13: F | C13: 82.87
A14: 45847 | B14: F | C14: 5.4
A15: 45853 | B15: T | C15: -96.08
A16: 45854 | B16: F | C16: 7.5
... A103: 46056 | B103: T | C103: -80

Sheet BODEGA MILAGRO
A1: CLIENTE | B1: BODEGA MILAGRO
A2: NOMBRE | B2: MILAGRO BARRETO
A3: TOTALES | C3: =SUM(C$4:C$1048576) -> 0.09 | D3: =SUM(D$4:D$1048576) -> 0 | E3: =SUM(E$5:E$1048576) -> 0 | F3: =SUM(F$5:F$1048576) -> 0 | G3: =SUM(G$5:G$1048576) -> 0
A4: FECHA | B4: F- E- T- | C4: DEUDA Y ABONOS | D4: VACIO 1/4 | E4: VACIO 350 | F4: VACIO 1.25 | G4: RETECION
A5: 45819 | B5: F | C5: 17.54
A6: 45819 | B6: F | C6: 93.91
A7: 45825 | B7: T | C7: -111.44
A8: 45826 | B8: F | C8: 26.46
A9: 45826 | B9: F | C9: 6.42
A10: 45833 | B10: T | C10: -32.88
A11: 45833 | B11: F | C11: 15.85
A12: 45833 | B12: F | C12: 36.14
A13: 45839 | B13: T | C13: -51.61
A14: 45840 | B14: F | C14: 7.5
A15: 45840 | B15: F | C15: 31.55
A16: 45840 | B16: F | C16: 6.42
... A97: 46052 | B97: F | C97: 17.28

Sheet BODEGA MILAGROS
A1: CLIENTE | B1: BODEGA MILAGROS
A2: NOMBRE | B2: MILAGROS ZAMBRANO
A3: TOTALES | C3: =SUM(C$4:C$1048576) -> 0.96 | D3: =SUM(D$4:D$1048576) -> 0 | E3: =SUM(E$5:E$1048576) -> 0 | F3: =SUM(F$5:F$1048576) -> 0 | G3: =SUM(G$5:G$1048576) -> 0
A4: FECHA | B4: F- E- T- | C4: DEUDA Y ABONOS | D4: VACIO 1/4 | E4: VACIO 350 | F4: VACIO 1.25 | G4: RETECION
A5: 45821 | B5: T | C5: -31.7
A6: 45821 | B6: F | C6: 31.7
A7: 45828 | B7: T | C7: -118.64
A8: 45828 | B8: F | C8: 118.64
A9: 45842 | B9: T | C9: -72.52
A10: 45842 | B10: F | C10: 15
A11: 45842 | B11: F | C11: 57.52
A12: 45849 | B12: T | C12: -15.54
A13: 45849 | B13: F | C13: 9.84
A14: 45849 | B14: F | C14: 5.58
A15: 45859 | B15: T | C15: -51.38
A16: 45856 | B16: F | C16: 51.38
... A40: 46013 | B40: T | C40: -61.38

Sheet BODEGA NANCYTA
A1: CLIENTE | B1: BODEGA NANCYTA
A2: NOMBRE | B2: NANCY MONSALVE
A3: TOTALES | C3: =SUM(C$4:C$1048576) -> 63.67 | D3: =SUM(D$4:D$1048576) -> 0 | E3: =SUM(E$5:E$1048576) -> 0 | F3: =SUM(F$5:F$1048576) -> 0 | G3: =SUM(G$5:G$1048576) -> 0
A4: FECHA | B4: F- E- T- | C4: DEUDA Y ABONOS | D4: VACIO 1/4 | E4: VACIO 350 | F4: VACIO 1.25 | G4: RETECION
A5: 45818 | B5: F | C5: 20.8
A6: 45818 | B6: F | C6: 25.69
A7: 45818 | B7: F | C7: 80.63
A8: 45825 | B8: E | C8: -128.53
A9: 45825 | B9: F | C9: 15.4
